/*
 * Промисификация:
 * - Поблема доступа к результату промиса с колбеком
 * - Функция которая возвращает промис
 */

const makeOrder = dish => {
  const DELAY = 1000;

  return new Promise((resolve, reject) => {
    const passed = Math.random() > 0.5;

    setTimeout(() => {
      if (passed) {
        resolve(`✅ Вот ваш заказ: ${dish}`);
      }

      reject('❌ Упс, у нас закончились продукты');
    }, DELAY);
  });
};

makeOrder('пирожок').then(onMakeOrderSuccess).catch(onMakeOrderError);

function onMakeOrderSuccess(result) {
  console.log('onMakeOrderSuccess');
  console.log(result);
}

function onMakeOrderError(error) {
  console.log('onMakeOrderError');
  console.log(error);
}

/*
 * Промисификация «синхронных» функций
 * - Promise.resolve()
 * - Promise.reject()
 */

const makeOrder1 = dish => {
  return Promise.resolve(`✅ Вот ваш заказ: ${dish}`);
};

makeOrder1('пирожок').then(onMakeOrderSuccess);

function onMakeOrderSuccess(result) {
  console.log('onMakeOrderSuccess');
  console.log(result);
}

function onMakeOrderError(error) {
  console.log('onMakeOrderError');
  console.log(error);
}

/*
 * Покемоны с https://pokeapi.co/
 */

const fetchPokemonById = id => {
  return fetch(`https://pokeapi.co/api/v2/pokemon/${id}`).then(r => r.json());
};

fetchPokemonById(1).then(onFetchSuccess).catch(onFetchError);

fetchPokemonById(2).then(onFetchSuccess).catch(onFetchError);

fetchPokemonById(3).then(onFetchSuccess).catch(onFetchError);

function onFetchSuccess(pokemon) {
  console.log('onFetchSuccess -> onFetchSuccess');
  console.log(pokemon);
}

function onFetchError(error) {
  console.log('onFetchError -> onFetchError');
  console.log('Это в блоке catch');
  console.log(error);
}

makePromise;
const makePromise = () => {
  return new Promise((resolve, reject) => {
    const passed = Math.random() > 0.5;

    setTimeout(() => {
      if (passed) {
        resolve('✅ Куку это resolve');
      }

      reject('❌ все пропало это reject');
    }, 2000);
  });
};

makePromise()
  .then(result => console.log(result))
  .catch(error => console.log(error));
